[2025-10-22 01:20:22,322: INFO: common: yaml file: config\config.yaml loaded successfully]
[2025-10-22 01:20:24,120: INFO: common: yaml file: config\config.yaml loaded successfully]
[2025-10-22 02:02:07,280: ERROR: 418161865: [Errno 2] No such file or directory: 'config\\config.yaml']
Traceback (most recent call last):
  File "C:\Users\aminu\AppData\Local\Temp\ipykernel_7832\418161865.py", line 2, in <module>
    config_manager = ConfigurationManager()
  File "C:\Users\aminu\AppData\Local\Temp\ipykernel_7832\2062214159.py", line 7, in __init__
    self.config = read_yaml(config_filepath)
  File "c:\Users\aminu\miniconda3\envs\textS\lib\site-packages\ensure\main.py", line 849, in __call__
    return_val = self.f(*args, **kwargs)
  File "D:\Version Control\AI-Text-Summarizer\src\textSummarizer\utils\common.py", line 35, in read_yaml
    raise e
  File "D:\Version Control\AI-Text-Summarizer\src\textSummarizer\utils\common.py", line 28, in read_yaml
    with open(path_to_yaml) as yaml_file:
FileNotFoundError: [Errno 2] No such file or directory: 'config\\config.yaml'
[2025-10-22 02:04:59,119: ERROR: 947058205: [Errno 2] No such file or directory: 'config\\config.yaml']
Traceback (most recent call last):
  File "C:\Users\aminu\AppData\Local\Temp\ipykernel_7832\947058205.py", line 2, in <module>
    config_manager = ConfigurationManager()
  File "C:\Users\aminu\AppData\Local\Temp\ipykernel_7832\2062214159.py", line 7, in __init__
    self.config = read_yaml(config_filepath)
  File "c:\Users\aminu\miniconda3\envs\textS\lib\site-packages\ensure\main.py", line 849, in __call__
    return_val = self.f(*args, **kwargs)
  File "D:\Version Control\AI-Text-Summarizer\src\textSummarizer\utils\common.py", line 35, in read_yaml
    raise e
  File "D:\Version Control\AI-Text-Summarizer\src\textSummarizer\utils\common.py", line 28, in read_yaml
    with open(path_to_yaml) as yaml_file:
FileNotFoundError: [Errno 2] No such file or directory: 'config\\config.yaml'
[2025-10-22 02:07:59,277: INFO: common: yaml file: config\config.yaml loaded successfully]
[2025-10-22 02:07:59,278: ERROR: 242053552: yaml file is empty]
Traceback (most recent call last):
  File "D:\Version Control\AI-Text-Summarizer\src\textSummarizer\utils\common.py", line 31, in read_yaml
    return ConfigBox(content)
  File "box\box.py", line 259, in box.box.Box.__init__
box.exceptions.BoxValueError: First argument must be mapping or iterable

During handling of the above exception, another exception occurred:

Traceback (most recent call last):
  File "C:\Users\aminu\AppData\Local\Temp\ipykernel_7832\242053552.py", line 2, in <module>
    config_manager = ConfigurationManager()
  File "C:\Users\aminu\AppData\Local\Temp\ipykernel_7832\2062214159.py", line 7, in __init__
    self.config = read_yaml(config_filepath)
  File "c:\Users\aminu\miniconda3\envs\textS\lib\site-packages\ensure\main.py", line 849, in __call__
    return_val = self.f(*args, **kwargs)
  File "D:\Version Control\AI-Text-Summarizer\src\textSummarizer\utils\common.py", line 33, in read_yaml
    raise ValueError("yaml file is empty")
ValueError: yaml file is empty
[2025-10-22 02:11:12,949: INFO: common: yaml file: config\config.yaml loaded successfully]
[2025-10-22 02:11:12,951: ERROR: 418161865: yaml file is empty]
Traceback (most recent call last):
  File "D:\Version Control\AI-Text-Summarizer\src\textSummarizer\utils\common.py", line 31, in read_yaml
    return ConfigBox(content)
  File "box\box.py", line 259, in box.box.Box.__init__
box.exceptions.BoxValueError: First argument must be mapping or iterable

During handling of the above exception, another exception occurred:

Traceback (most recent call last):
  File "C:\Users\aminu\AppData\Local\Temp\ipykernel_7832\418161865.py", line 2, in <module>
    config_manager = ConfigurationManager()
  File "C:\Users\aminu\AppData\Local\Temp\ipykernel_7832\2062214159.py", line 7, in __init__
    self.config = read_yaml(config_filepath)
  File "c:\Users\aminu\miniconda3\envs\textS\lib\site-packages\ensure\main.py", line 849, in __call__
    return_val = self.f(*args, **kwargs)
  File "D:\Version Control\AI-Text-Summarizer\src\textSummarizer\utils\common.py", line 33, in read_yaml
    raise ValueError("yaml file is empty")
ValueError: yaml file is empty
[2025-10-22 11:07:03,177: ERROR: 136320435: Error during data validation: [Errno 2] No such file or directory: 'config\\config.yaml']
[2025-10-22 11:08:04,846: ERROR: 2346963498: Error during data validation: [Errno 2] No such file or directory: 'config\\config.yaml']
[2025-10-22 11:10:53,790: ERROR: 3372476238: Error in data validation process: [Errno 2] No such file or directory: 'config\\config.yaml']
[2025-10-22 11:23:00,401: INFO: common: yaml file: config\config.yaml loaded successfully]
[2025-10-22 11:23:00,405: INFO: common: yaml file: config\params.yaml loaded successfully]
[2025-10-22 11:28:16,691: INFO: common: yaml file: config\config.yaml loaded successfully]
[2025-10-22 11:28:16,693: INFO: common: yaml file: config\params.yaml loaded successfully]
[2025-10-22 11:29:13,110: INFO: common: yaml file: config\config.yaml loaded successfully]
[2025-10-22 11:29:13,113: INFO: common: yaml file: config\params.yaml loaded successfully]
[2025-10-22 11:37:46,868: INFO: common: yaml file: config\config.yaml loaded successfully]
[2025-10-22 11:37:46,872: INFO: common: yaml file: config\params.yaml loaded successfully]
[2025-10-22 11:40:02,529: INFO: common: yaml file: config\config.yaml loaded successfully]
[2025-10-22 11:40:02,533: INFO: common: yaml file: config\params.yaml loaded successfully]
[2025-10-22 11:40:05,156: INFO: common: yaml file: D:\Version Control\AI-Text-Summarizer\config\config.yaml loaded successfully]
[2025-10-22 11:40:05,159: INFO: common: yaml file: D:\Version Control\AI-Text-Summarizer\config\params.yaml loaded successfully]
[2025-10-22 11:40:05,161: INFO: common: created directory at: artifacts]
[2025-10-22 11:40:05,164: INFO: common: created directory at: artifacts/data_validation]
[2025-10-22 11:42:34,422: INFO: common: yaml file: D:\Version Control\AI-Text-Summarizer\config\config.yaml loaded successfully]
[2025-10-22 11:42:34,425: INFO: common: yaml file: D:\Version Control\AI-Text-Summarizer\config\params.yaml loaded successfully]
[2025-10-22 11:42:34,426: INFO: common: created directory at: artifacts]
[2025-10-22 11:42:34,427: INFO: common: created directory at: artifacts/data_validation]
[2025-10-22 11:44:02,141: INFO: common: yaml file: D:\Version Control\AI-Text-Summarizer\config\config.yaml loaded successfully]
[2025-10-22 11:44:02,145: INFO: common: yaml file: D:\Version Control\AI-Text-Summarizer\config\params.yaml loaded successfully]
[2025-10-22 11:44:02,146: INFO: common: created directory at: artifacts]
[2025-10-22 11:44:02,148: INFO: common: created directory at: artifacts/data_validation]
[2025-10-22 11:44:02,150: ERROR: 2811241978: Error occurred: [WinError 3] The system cannot find the path specified: 'artifacts\\data_ingestion\\Samsum_dataset']
[2025-10-22 11:47:26,935: INFO: common: yaml file: D:\Version Control\AI-Text-Summarizer\config\config.yaml loaded successfully]
[2025-10-22 11:47:26,939: INFO: common: yaml file: D:\Version Control\AI-Text-Summarizer\config\params.yaml loaded successfully]
[2025-10-22 11:47:26,940: INFO: common: created directory at: artifacts]
[2025-10-22 11:47:26,941: INFO: common: created directory at: artifacts/data_validation]
[2025-10-22 11:47:58,655: INFO: common: yaml file: D:\Version Control\AI-Text-Summarizer\config\config.yaml loaded successfully]
[2025-10-22 11:47:58,657: INFO: common: yaml file: D:\Version Control\AI-Text-Summarizer\config\params.yaml loaded successfully]
[2025-10-22 11:47:58,659: INFO: common: created directory at: artifacts]
[2025-10-22 11:47:58,661: INFO: common: created directory at: artifacts/data_validation]
[2025-10-22 11:48:10,432: INFO: common: yaml file: D:\Version Control\AI-Text-Summarizer\config\config.yaml loaded successfully]
[2025-10-22 11:48:10,436: INFO: common: yaml file: D:\Version Control\AI-Text-Summarizer\config\params.yaml loaded successfully]
[2025-10-22 11:48:10,438: INFO: common: created directory at: artifacts]
[2025-10-22 11:48:10,440: INFO: common: created directory at: artifacts/data_validation]
[2025-10-22 11:48:12,499: INFO: common: yaml file: D:\Version Control\AI-Text-Summarizer\config\config.yaml loaded successfully]
[2025-10-22 11:48:12,502: INFO: common: yaml file: D:\Version Control\AI-Text-Summarizer\config\params.yaml loaded successfully]
[2025-10-22 11:48:12,503: INFO: common: created directory at: artifacts]
[2025-10-22 11:48:12,505: INFO: common: created directory at: artifacts/data_validation]
[2025-10-22 11:50:00,760: INFO: common: yaml file: D:\Version Control\AI-Text-Summarizer\config\config.yaml loaded successfully]
[2025-10-22 11:50:00,762: INFO: common: yaml file: D:\Version Control\AI-Text-Summarizer\config\params.yaml loaded successfully]
[2025-10-22 11:50:00,763: INFO: common: created directory at: artifacts]
[2025-10-22 11:50:00,765: INFO: common: created directory at: artifacts/data_validation]
[2025-10-22 11:50:14,357: INFO: common: yaml file: D:\Version Control\AI-Text-Summarizer\config\config.yaml loaded successfully]
[2025-10-22 11:50:14,359: INFO: common: yaml file: D:\Version Control\AI-Text-Summarizer\config\params.yaml loaded successfully]
[2025-10-22 11:50:14,361: INFO: common: created directory at: artifacts]
[2025-10-22 11:50:14,362: INFO: common: created directory at: artifacts/data_validation]
[2025-10-22 11:52:24,028: INFO: common: yaml file: D:\Version Control\AI-Text-Summarizer\config\config.yaml loaded successfully]
[2025-10-22 11:52:24,030: INFO: common: yaml file: D:\Version Control\AI-Text-Summarizer\config\params.yaml loaded successfully]
[2025-10-22 11:52:24,031: INFO: common: created directory at: artifacts]
[2025-10-22 11:52:24,033: INFO: common: created directory at: artifacts/data_validation]
[2025-10-22 11:52:24,034: ERROR: 2657587287: Error occurred: 'DataValidation' object has no attribute 'validate_required_files']
[2025-10-22 11:53:14,118: INFO: common: yaml file: D:\Version Control\AI-Text-Summarizer\config\config.yaml loaded successfully]
[2025-10-22 11:53:14,120: INFO: common: yaml file: D:\Version Control\AI-Text-Summarizer\config\params.yaml loaded successfully]
[2025-10-22 11:53:14,122: INFO: common: created directory at: artifacts]
[2025-10-22 11:53:14,124: INFO: common: created directory at: artifacts/data_validation]
[2025-10-22 11:53:14,126: ERROR: 2657587287: Error occurred: [WinError 3] The system cannot find the path specified: 'artifacts\\data_ingestion\\Samsum_dataset']
[2025-10-22 11:55:30,511: INFO: common: yaml file: D:\Version Control\AI-Text-Summarizer\config\config.yaml loaded successfully]
[2025-10-22 11:55:30,514: INFO: common: yaml file: D:\Version Control\AI-Text-Summarizer\config\params.yaml loaded successfully]
[2025-10-22 11:55:30,515: INFO: common: created directory at: artifacts]
[2025-10-22 11:55:30,517: INFO: common: created directory at: artifacts/data_validation]
[2025-10-22 11:55:30,519: ERROR: 2657587287: Error occurred: [WinError 3] The system cannot find the path specified: 'artifacts\\data_ingestion\\Samsum_dataset']
[2025-10-22 12:07:22,949: ERROR: 1280034819: Error occurred: name 'ConfigurationManager' is not defined]
[2025-10-22 12:08:13,324: ERROR: 1280034819: Error occurred: [Errno 2] No such file or directory: 'config\\config.yaml']
[2025-10-22 12:09:12,968: ERROR: 1280034819: Error occurred: [Errno 2] No such file or directory: 'd:\\Version Control\\AI-Text-Summarizer\\research\\config\\config.yaml']
[2025-10-22 12:12:48,485: ERROR: 1280034819: Error occurred: [Errno 2] No such file or directory: 'd:\\Version Control\\AI-Text-Summarizer\\research\\config\\config.yaml']
[2025-10-22 12:13:10,916: INFO: common: yaml file: config\config.yaml loaded successfully]
[2025-10-22 12:13:10,920: INFO: common: yaml file: config\params.yaml loaded successfully]
[2025-10-22 12:15:14,435: ERROR: 1143734415: An error occurred: [Errno 2] No such file or directory: 'd:\\Version Control\\AI-Text-Summarizer\\research\\config\\config.yaml']
Traceback (most recent call last):
  File "C:\Users\aminu\AppData\Local\Temp\ipykernel_21208\1143734415.py", line 2, in <module>
    config = ConfigurationManager()
  File "C:\Users\aminu\AppData\Local\Temp\ipykernel_21208\2254210527.py", line 13, in __init__
    self.config = read_yaml(config_filepath)
  File "c:\Users\aminu\miniconda3\envs\textS\lib\site-packages\ensure\main.py", line 849, in __call__
    return_val = self.f(*args, **kwargs)
  File "D:\Version Control\AI-Text-Summarizer\src\textSummarizer\utils\common.py", line 32, in read_yaml
    raise e
  File "D:\Version Control\AI-Text-Summarizer\src\textSummarizer\utils\common.py", line 21, in read_yaml
    with open(path_to_yaml, 'r') as yaml_file:
FileNotFoundError: [Errno 2] No such file or directory: 'd:\\Version Control\\AI-Text-Summarizer\\research\\config\\config.yaml'
[2025-10-22 12:17:15,391: ERROR: 268186454: An error occurred: [Errno 2] No such file or directory: 'd:\\Version Control\\AI-Text-Summarizer\\research\\config\\config.yaml']
Traceback (most recent call last):
  File "C:\Users\aminu\AppData\Local\Temp\ipykernel_21208\268186454.py", line 2, in <module>
    config = ConfigurationManager()
  File "C:\Users\aminu\AppData\Local\Temp\ipykernel_21208\2254210527.py", line 13, in __init__
    self.config = read_yaml(config_filepath)
  File "c:\Users\aminu\miniconda3\envs\textS\lib\site-packages\ensure\main.py", line 849, in __call__
    return_val = self.f(*args, **kwargs)
  File "D:\Version Control\AI-Text-Summarizer\src\textSummarizer\utils\common.py", line 32, in read_yaml
    raise e
  File "D:\Version Control\AI-Text-Summarizer\src\textSummarizer\utils\common.py", line 21, in read_yaml
    with open(path_to_yaml, 'r') as yaml_file:
FileNotFoundError: [Errno 2] No such file or directory: 'd:\\Version Control\\AI-Text-Summarizer\\research\\config\\config.yaml'
